Workbook
Name ACTION: #REF!

Sheet Cover
B2: UNIT TEST CASE
A4: Project Name | B4: FitSocial (SEP490 - Capstone Project) | E4: Creator | F4: SEP490 Team
A5: Project Code | B5: SEP490_FitSocial | E5: Reviewer/Approver | F5: Lead Reviewer
A6: Document Code | B6: SEP490_FitSocial_UT_v1.0 | E6: Issue Date | F6: 31/10/2026
E7: Version
A10: Record of change
A11: Effective Date | B11: Version | C11: Change Item | D11: *A,D,M | E11: Change description | F11: Reference
A12: 22/10/2026 | B12: 1 | C12: TC01, TC02 | D12: A | E12: Mô tả thay đổi cái gì… | F12: Có tham chiếu tài liệu nào ko? Có thì liệt kê ra, ko thì bỏ trống
A13: 21/10/2026 | B13: 1.1 | C13: TC02, TC03 | D13: M, A | E13: Chỉnh sửa TC02. Thêm mới TC03 | F13: …
A14: 31/10/2026 | B14: 1.2 | C14: UTCID01 - UTCID16 | D14: A | E14: Add Unit Test cases for View Own Profile (GetOwnProfileAsync). | F14: UserService.cs

Sheet FunctionList
E2: UNIT TEST CASE LIST
A4: Project Name | E4: FitSocial (SEP490 - Capstone Project)
A5: Project Code | E5: SEP490_FitSocial
A6: Normal number of Test cases/KLOC | E6: 100
A7: Test Environment Setup Description | E7: .NET 8.0 SDK, xUnit 2.9.3, Moq 4.21.0, Coverlet.collector 6.0.4, Visual Studio 2022 / VS Code, Windows 11
A10: No | B10: Requirement Name | C10: Class Name | D10: Function Name | E10: Function Code(Optional) | F10: Sheet Name | G10: Description | H10: Pre-Condition
A11: 1 | C11: Class1 | D11: Function A | E11: AuthLogin | F11: Function1_Đăng Nhập
A12: 2 | C12: Class2 | D12: Function B | E12: Function2 | F12: Function2
A13: 3 | C13: Class3 | D13: Function C | E13: Function3 | F13: Function3
A14: 4 | B14: View Own Profile | C14: UserService | D14: GetOwnProfileAsync | E14: UC05_GetOwnProfile | F14: ViewOwnProfile | G14: Retrieves the profile information of the currently authenticated Trainee or Coach user, including personal profile attributes and coach certificate status. | H14: User is authenticated with a valid userId and the account is not locked.
E25: Tên hàm trong code | F25: Tên của sheet

Sheet Function1_Đăng nhập
A2: Function Code | C2: =FunctionList!E11 -> AuthLogin | F2: Function Name | L2: =FunctionList!D11 -> Function A
A3: Created By | C3: <Developer Name> | F3: Executed By
A4: Lines of code | C4: 100 | F4: Lack of test cases | L4: =IF(FunctionList!E6<>"N/A",SUM(C4*FunctionList!E6/1000,- O7),"N/A") -> -5
A5: Test requirement | C5: <Brief description about requirements which are tested in this function>
A6: Passed | C6: Failed | F6: Untested | L6: N/A/B | O6: Total Test Cases
A7: =COUNTIF(F43:HQ43,"P") -> 12 | C7: =COUNTIF(F43:HQ43,"F") -> 2 | F7: =SUM(O7,- A7,- C7) -> 1 | L7: =COUNTIF(E42:HQ42,"N") -> 11 | M7: =COUNTIF(E42:HQ42,"A") -> 3 | N7: =COUNTIF(E42:HQ42,"B") -> 1 | O7: =COUNTA(E9:HT9) -> 15
F9: UTCID01 | G9: UTCID02 | H9: UTCID03 | I9: UTCID04 | J9: UTCID05 | K9: UTCID06 | L9: UTCID07 | M9: UTCID08 | N9: UTCID09 | O9: UTCID10 | P9: UTCID11 | Q9: UTCID12 | R9: UTCID13 | S9: UTCID14 | T9: UTCID15
A10: Condition | B10: Precondition
D11: Can connect with server | F11: O | G11: O
D12: Nguoi dung phai co account | F12: O | G12: O
D13: Pre 1 | G13: O
D14: Pre 2
B15: Username
D16: "" | G16: O
D17: nguyenvana | F17: O
D18: a
D19: nguyen van
D20: nguyenvan@ | H20: O
B21: Password
D22: 12345 | F22: O | G22: O
D23: ""
D24: Admin@123
D25: abc
A34: Confirm | B34: Return
D35: T | F35: O | X35: Nhập số từ 5 - 20
D36: F | G36: O | Y36: Normal: 6-19
B37: Exception | Y37: Boundary: 5,20
J38: O | Y38: Abnormal: <5;>20
A42: Result | B42: Type(N : Normal, A : Abnormal, B : Boundary) | F42: A | G42: N | H42: N | I42: N | J42: N | K42: B | L42: A | M42: N | N42: N | O42: N | P42: N | Q42: N | R42: A | S42: N | T42: N
B43: Passed/Failed | F43: P | G43: P | H43: P | I43: P | J43: P | K43: F | L43: F | M43: P | N43: P | O43: P | P43: P | Q43: P | S43: P | T43: P
B44: Executed Date | F44: 39139 | G44: 39139 | H44: 39140 | I44: 39141 | J44: 39142 | K44: 39143 | L44: 39144 | M44: 39145 | N44: 39146 | O44: 39147 | P44: 39148 | Q44: 39149 | R44: 39150 | S44: 39151 | T44: 39152
B45: Defect ID | K45: DFID002 | L45: DFID004 | M45: DFID005 | N45: DFID006 | O45: DFID007 | P45: DFID008 | Q45: DFID009 | R45: DFID010 | S45: DFID011 | T45: DFID012

Sheet ViewOwnProfile
A2: Function Code | C2: UC05_GetOwnProfile | F2: Function Name | L2: GetOwnProfileAsync
A3: Created By | C3: Antigravity Pair Programmer | F3: Executed By | L3: QA / Antigravity
A4: Lines of code | C4: 67 | F4: Lack of test cases | L4: =IF(FunctionList!E6<>"N/A",SUM(C4*FunctionList!E6/1000,- O7),"N/A") -> -9.3
A5: Test requirement | C5: Retrieves current authenticated user's own profile for Trainees and Coaches, enforcing account lock checks, normalizing roles, and computing coach certificate expirations.
A6: Passed | C6: Failed | F6: Untested | L6: N / A / B | O6: Total Test Cases
A7: =COUNTIF(F43:HQ43,"P") -> 16 | C7: =COUNTIF(F43:HQ43,"F") -> 0 | F7: =SUM(O7,- A7,- C7) -> 0 | L7: =COUNTIF(F42:HQ42,"N") -> 3 | M7: =COUNTIF(F42:HQ42,"A") -> 4 | N7: =COUNTIF(F42:HQ42,"B") -> 9 | O7: =COUNTA(F9:HQ9) -> 16
F9: UTCID01 | G9: UTCID02 | H9: UTCID03 | I9: UTCID04 | J9: UTCID05 | K9: UTCID06 | L9: UTCID07 | M9: UTCID08 | N9: UTCID09 | O9: UTCID10 | P9: UTCID11 | Q9: UTCID12 | R9: UTCID13 | S9: UTCID14 | T9: UTCID15 | U9: UTCID16
A10: Condition | B10: Precondition
B11: User Exists in Database | D11: user != null (User found) | F11: O | G11: O | H11: O | J11: O | M11: O | N11: O | O11: O | P11: O | Q11: O | R11: O | S11: O | T11: O | U11: O
D12: user == null (Not found) | I12: O
B13: Account Lock Status
D14: IsLocked = false | F14: O | G14: O | H14: O | M14: O | N14: O | O14: O | P14: O | Q14: O | R14: O | S14: O | U14: O
D15: IsLocked = true | J15: O
D16: IsLocked = null | T16: O
B17: User Role Code
D18: RoleCode = "COACH" | F18: O | H18: O | M18: O | N18: O | O18: O | P18: O
D19: RoleCode = "TRAINEE" | G19: O | J19: O | Q19: O
D20: RoleCode = null | R20: O
D21: RoleCode = "STAFF" | S21: O
D22: RoleCode = " coach " | U22: O
B23: Coach Profile & Certificates
D24: CoachProfileCoach = null | M24: O
D25: CoachCertificates = [Valid("APPROVED", Expiry > today), Expired("APPROVED", Expiry < today)] | F25: O
D26: CoachCertificates = [Valid("APPROVED", Expiry > today)] | H26: O
D27: CoachCertificates = [] (Count = 0) | N27: O
D28: CoachCertificates = [Expired("APPROVED", Expiry < today)] | O28: O
D29: CoachCertificates = [Pending("PENDING", Expiry > today)] | P29: O
B30: User FullName Attribute
D31: FullName = null | Q31: O
B32: Repository & Cancellation Behavior | D32: Repo throws InvalidOperationException("Database connection failure") | K32: O
D33: CancellationToken.IsCancellationRequested = true | L33: O
A34: Confirm | B34: Return
D35: Return CoachProfileDto with Success=true | F35: T | H35: T | M35: T | N35: T | O35: T | P35: T | U35: T
D36: Return TraineeProfileDto with Success=true | G36: T | Q36: T | R36: T | S36: T | T36: T
B37: Exception
D38: NotFoundException (User profile could not be found.) | I38: E
D39: ForbiddenException (Account locked) | J39: E
D40: InvalidOperationException (DB connection error) | K40: E
D41: OperationCanceledException | L41: E
A42: Result | B42: Type(N : Normal, A : Abnormal, B : Boundary) | F42: N | G42: N | H42: N | I42: A | J42: A | K42: A | L42: A | M42: B | N42: B | O42: B | P42: B | Q42: B | R42: B | S42: B | T42: B | U42: B
...

Sheet Example
A2: Function Code | C2: =FunctionList!E11 -> AuthLogin | F2: Function Name | L2: =FunctionList!D11 -> Function A
A3: Created By | C3: <Developer Name> | F3: Executed By
A4: Lines of code | C4: 100 | F4: Lack of test cases | L4: =IF(FunctionList!E6<>"N/A",SUM(C4*FunctionList!E6/1000,- O7),"N/A") -> -5
A5: Test requirement | C5: <Brief description about requirements which are tested in this function>
A6: Passed | C6: Failed | F6: Untested | L6: N/A/B | O6: Total Test Cases
A7: =COUNTIF(F47:HQ47,"P") -> 0 | C7: =COUNTIF(F47:HQ47,"F") -> 0 | F7: =SUM(O7,- A7,- C7) -> 15 | L7: =COUNTIF(E46:HQ46,"N") -> 0 | M7: =COUNTIF(E46:HQ46,"A") -> 0 | N7: =COUNTIF(E46:HQ46,"B") -> 0 | O7: =COUNTA(E9:HT9) -> 15
F9: UTCID01 | G9: UTCID02 | H9: UTCID02 | I9: UTCID02 | J9: UTCID02 | K9: UTCID02 | L9: UTCID07 | M9: UTCID08 | N9: UTCID09 | O9: UTCID10 | P9: UTCID11 | Q9: UTCID12 | R9: UTCID13 | S9: UTCID14 | T9: UTCID15
A10: Condition | B10: Precondition
B14: a
D15: -2 | F15: O
D16: -1 | L16: O
D17: 0 | G17: O | H17: O | I17: O
D18: 1 | J18: O | K18: O
B19: b
D20: 0 | G20: O | H20: O
D21: -2 | J21: O | K21: O | L21: O
D22: 2 | I22: O
B23: c
D24: 0 | G24: O
D25: 1 | H25: O | I25: O | J25: O
D26: 3 | L26: O
D27: 5 | K27: O
A33: Confirm | B33: Return
B34: list
D35: null | F35: O | H35: O | K35: O
D36: size = 0 | G36: O
D37: {-1/2} | I37: O
D38: {1,1} | J38: O
D39: {1,-3} | L39: O
B40: Exception
B42: Log message
D43: "please input a>= -1" | F43: O
A45: Result | B45: Type(N : Normal, A : Abnormal, B : Boundary) | F45: A | G45: N | H45: N | I45: N | J45: N | K45: N | L45: B
B46: Passed/Failed
B47: Executed Date | F47: 39139 | G47: 39139 | H47: 39139 | I47: 39139 | J47: 39139 | K47: 39139 | L47: 39144
B48: Defect ID
